[2025-03-07T10:48:20.553+0000] {taskinstance.py:1159} INFO - Dependencies all met for dep_context=non-requeueable deps ti=<TaskInstance: dag_with_postgres_operator_v03.create_postgres_table scheduled__2025-03-04T00:00:00+00:00 [queued]>
[2025-03-07T10:48:20.561+0000] {taskinstance.py:1159} INFO - Dependencies all met for dep_context=requeueable deps ti=<TaskInstance: dag_with_postgres_operator_v03.create_postgres_table scheduled__2025-03-04T00:00:00+00:00 [queued]>
[2025-03-07T10:48:20.561+0000] {taskinstance.py:1361} INFO - Starting attempt 2 of 6
[2025-03-07T10:48:20.581+0000] {taskinstance.py:1382} INFO - Executing <Task(PostgresOperator): create_postgres_table> on 2025-03-04 00:00:00+00:00
[2025-03-07T10:48:20.586+0000] {standard_task_runner.py:57} INFO - Started process 760 to run task
[2025-03-07T10:48:20.590+0000] {standard_task_runner.py:84} INFO - Running: ['***', 'tasks', 'run', 'dag_with_postgres_operator_v03', 'create_postgres_table', 'scheduled__2025-03-04T00:00:00+00:00', '--job-id', '48', '--raw', '--subdir', 'DAGS_FOLDER/postgres_operator.py', '--cfg-path', '/tmp/tmpv144x321']
[2025-03-07T10:48:20.594+0000] {standard_task_runner.py:85} INFO - Job 48: Subtask create_postgres_table
[2025-03-07T10:48:20.653+0000] {task_command.py:416} INFO - Running <TaskInstance: dag_with_postgres_operator_v03.create_postgres_table scheduled__2025-03-04T00:00:00+00:00 [running]> on host 93934f8e361f
[2025-03-07T10:48:20.739+0000] {taskinstance.py:1662} INFO - Exporting env vars: AIRFLOW_CTX_DAG_OWNER='***' AIRFLOW_CTX_DAG_ID='dag_with_postgres_operator_v03' AIRFLOW_CTX_TASK_ID='create_postgres_table' AIRFLOW_CTX_EXECUTION_DATE='2025-03-04T00:00:00+00:00' AIRFLOW_CTX_TRY_NUMBER='2' AIRFLOW_CTX_DAG_RUN_ID='scheduled__2025-03-04T00:00:00+00:00'
[2025-03-07T10:48:20.740+0000] {sql.py:274} INFO - Executing: 
            create table if not exists dag_runs (
                dt date,
                dag_id character varying,
                primary key (dt, dag_id)
            )
        
[2025-03-07T10:48:20.746+0000] {base.py:73} INFO - Using connection ID 'postgres_localhost' for task execution.
[2025-03-07T10:48:20.755+0000] {base.py:73} INFO - Using connection ID 'postgres_localhost' for task execution.
[2025-03-07T10:48:20.756+0000] {taskinstance.py:1937} ERROR - Task failed with exception
Traceback (most recent call last):
  File "/home/airflow/.local/lib/python3.8/site-packages/airflow/providers/common/sql/operators/sql.py", line 280, in execute
    output = hook.run(
  File "/home/airflow/.local/lib/python3.8/site-packages/airflow/providers/common/sql/hooks/sql.py", line 385, in run
    with closing(self.get_conn()) as conn:
  File "/home/airflow/.local/lib/python3.8/site-packages/airflow/providers/postgres/hooks/postgres.py", line 155, in get_conn
    self.conn = psycopg2.connect(**conn_args)
  File "/home/airflow/.local/lib/python3.8/site-packages/psycopg2/__init__.py", line 122, in connect
    conn = _connect(dsn, connection_factory=connection_factory, **kwasync)
psycopg2.OperationalError: connection to server at "localhost" (::1), port 5432 failed: Connection refused
	Is the server running on that host and accepting TCP/IP connections?
connection to server at "localhost" (127.0.0.1), port 5432 failed: Connection refused
	Is the server running on that host and accepting TCP/IP connections?

[2025-03-07T10:48:20.764+0000] {taskinstance.py:1400} INFO - Marking task as UP_FOR_RETRY. dag_id=dag_with_postgres_operator_v03, task_id=create_postgres_table, execution_date=20250304T000000, start_date=20250307T104820, end_date=20250307T104820
[2025-03-07T10:48:20.775+0000] {standard_task_runner.py:104} ERROR - Failed to execute job 48 for task create_postgres_table (connection to server at "localhost" (::1), port 5432 failed: Connection refused
	Is the server running on that host and accepting TCP/IP connections?
connection to server at "localhost" (127.0.0.1), port 5432 failed: Connection refused
	Is the server running on that host and accepting TCP/IP connections?
; 760)
[2025-03-07T10:48:20.802+0000] {local_task_job_runner.py:228} INFO - Task exited with return code 1
[2025-03-07T10:48:20.824+0000] {taskinstance.py:2778} INFO - 0 downstream tasks scheduled from follow-on schedule check
[2025-03-07T10:57:57.848+0000] {taskinstance.py:1159} INFO - Dependencies all met for dep_context=non-requeueable deps ti=<TaskInstance: dag_with_postgres_operator_v03.create_postgres_table scheduled__2025-03-04T00:00:00+00:00 [queued]>
[2025-03-07T10:57:57.868+0000] {taskinstance.py:1159} INFO - Dependencies all met for dep_context=requeueable deps ti=<TaskInstance: dag_with_postgres_operator_v03.create_postgres_table scheduled__2025-03-04T00:00:00+00:00 [queued]>
[2025-03-07T10:57:57.868+0000] {taskinstance.py:1361} INFO - Starting attempt 2 of 6
[2025-03-07T10:57:57.887+0000] {taskinstance.py:1382} INFO - Executing <Task(PostgresOperator): create_postgres_table> on 2025-03-04 00:00:00+00:00
[2025-03-07T10:57:57.897+0000] {standard_task_runner.py:57} INFO - Started process 622 to run task
[2025-03-07T10:57:57.900+0000] {standard_task_runner.py:84} INFO - Running: ['***', 'tasks', 'run', 'dag_with_postgres_operator_v03', 'create_postgres_table', 'scheduled__2025-03-04T00:00:00+00:00', '--job-id', '13', '--raw', '--subdir', 'DAGS_FOLDER/postgres_operator.py', '--cfg-path', '/tmp/tmpeq2ku1ix']
[2025-03-07T10:57:57.902+0000] {standard_task_runner.py:85} INFO - Job 13: Subtask create_postgres_table
[2025-03-07T10:57:57.956+0000] {task_command.py:416} INFO - Running <TaskInstance: dag_with_postgres_operator_v03.create_postgres_table scheduled__2025-03-04T00:00:00+00:00 [running]> on host 5588030d4cfa
[2025-03-07T10:57:58.026+0000] {taskinstance.py:1662} INFO - Exporting env vars: AIRFLOW_CTX_DAG_OWNER='***' AIRFLOW_CTX_DAG_ID='dag_with_postgres_operator_v03' AIRFLOW_CTX_TASK_ID='create_postgres_table' AIRFLOW_CTX_EXECUTION_DATE='2025-03-04T00:00:00+00:00' AIRFLOW_CTX_TRY_NUMBER='2' AIRFLOW_CTX_DAG_RUN_ID='scheduled__2025-03-04T00:00:00+00:00'
[2025-03-07T10:57:58.027+0000] {sql.py:274} INFO - Executing: 
            create table if not exists dag_runs (
                dt date,
                dag_id character varying,
                primary key (dt, dag_id)
            )
        
[2025-03-07T10:57:58.034+0000] {base.py:73} INFO - Using connection ID 'postgres_localhost' for task execution.
[2025-03-07T10:57:58.041+0000] {base.py:73} INFO - Using connection ID 'postgres_localhost' for task execution.
[2025-03-07T10:57:58.043+0000] {taskinstance.py:1937} ERROR - Task failed with exception
Traceback (most recent call last):
  File "/home/airflow/.local/lib/python3.8/site-packages/airflow/providers/common/sql/operators/sql.py", line 280, in execute
    output = hook.run(
  File "/home/airflow/.local/lib/python3.8/site-packages/airflow/providers/common/sql/hooks/sql.py", line 385, in run
    with closing(self.get_conn()) as conn:
  File "/home/airflow/.local/lib/python3.8/site-packages/airflow/providers/postgres/hooks/postgres.py", line 155, in get_conn
    self.conn = psycopg2.connect(**conn_args)
  File "/home/airflow/.local/lib/python3.8/site-packages/psycopg2/__init__.py", line 122, in connect
    conn = _connect(dsn, connection_factory=connection_factory, **kwasync)
psycopg2.OperationalError: connection to server at "localhost" (::1), port 5432 failed: Connection refused
	Is the server running on that host and accepting TCP/IP connections?
connection to server at "localhost" (127.0.0.1), port 5432 failed: Connection refused
	Is the server running on that host and accepting TCP/IP connections?

[2025-03-07T10:57:58.050+0000] {taskinstance.py:1400} INFO - Marking task as UP_FOR_RETRY. dag_id=dag_with_postgres_operator_v03, task_id=create_postgres_table, execution_date=20250304T000000, start_date=20250307T105757, end_date=20250307T105758
[2025-03-07T10:57:58.065+0000] {standard_task_runner.py:104} ERROR - Failed to execute job 13 for task create_postgres_table (connection to server at "localhost" (::1), port 5432 failed: Connection refused
	Is the server running on that host and accepting TCP/IP connections?
connection to server at "localhost" (127.0.0.1), port 5432 failed: Connection refused
	Is the server running on that host and accepting TCP/IP connections?
; 622)
[2025-03-07T10:57:58.074+0000] {local_task_job_runner.py:228} INFO - Task exited with return code 1
[2025-03-07T10:57:58.094+0000] {taskinstance.py:2778} INFO - 0 downstream tasks scheduled from follow-on schedule check
[2025-03-07T11:32:45.970+0000] {taskinstance.py:1159} INFO - Dependencies all met for dep_context=non-requeueable deps ti=<TaskInstance: dag_with_postgres_operator_v03.create_postgres_table scheduled__2025-03-04T00:00:00+00:00 [queued]>
[2025-03-07T11:32:45.978+0000] {taskinstance.py:1159} INFO - Dependencies all met for dep_context=requeueable deps ti=<TaskInstance: dag_with_postgres_operator_v03.create_postgres_table scheduled__2025-03-04T00:00:00+00:00 [queued]>
[2025-03-07T11:32:45.978+0000] {taskinstance.py:1361} INFO - Starting attempt 2 of 6
[2025-03-07T11:32:46.016+0000] {taskinstance.py:1382} INFO - Executing <Task(PostgresOperator): create_postgres_table> on 2025-03-04 00:00:00+00:00
[2025-03-07T11:32:46.020+0000] {standard_task_runner.py:57} INFO - Started process 852 to run task
[2025-03-07T11:32:46.023+0000] {standard_task_runner.py:84} INFO - Running: ['***', 'tasks', 'run', 'dag_with_postgres_operator_v03', 'create_postgres_table', 'scheduled__2025-03-04T00:00:00+00:00', '--job-id', '17', '--raw', '--subdir', 'DAGS_FOLDER/postgres_operator.py', '--cfg-path', '/tmp/tmptllm3b6s']
[2025-03-07T11:32:46.025+0000] {standard_task_runner.py:85} INFO - Job 17: Subtask create_postgres_table
[2025-03-07T11:32:46.072+0000] {task_command.py:416} INFO - Running <TaskInstance: dag_with_postgres_operator_v03.create_postgres_table scheduled__2025-03-04T00:00:00+00:00 [running]> on host 5837dac536a6
[2025-03-07T11:32:46.135+0000] {taskinstance.py:1662} INFO - Exporting env vars: AIRFLOW_CTX_DAG_OWNER='***' AIRFLOW_CTX_DAG_ID='dag_with_postgres_operator_v03' AIRFLOW_CTX_TASK_ID='create_postgres_table' AIRFLOW_CTX_EXECUTION_DATE='2025-03-04T00:00:00+00:00' AIRFLOW_CTX_TRY_NUMBER='2' AIRFLOW_CTX_DAG_RUN_ID='scheduled__2025-03-04T00:00:00+00:00'
[2025-03-07T11:32:46.135+0000] {sql.py:274} INFO - Executing: 
            create table if not exists dag_runs (
                dt date,
                dag_id character varying,
                primary key (dt, dag_id)
            )
        
[2025-03-07T11:32:46.143+0000] {base.py:73} INFO - Using connection ID 'postgres_localhost' for task execution.
[2025-03-07T11:32:46.152+0000] {base.py:73} INFO - Using connection ID 'postgres_localhost' for task execution.
[2025-03-07T11:32:46.155+0000] {sql.py:418} INFO - Running statement: 
            create table if not exists dag_runs (
                dt date,
                dag_id character varying,
                primary key (dt, dag_id)
            )
        , parameters: None
[2025-03-07T11:32:46.165+0000] {taskinstance.py:1400} INFO - Marking task as SUCCESS. dag_id=dag_with_postgres_operator_v03, task_id=create_postgres_table, execution_date=20250304T000000, start_date=20250307T113245, end_date=20250307T113246
[2025-03-07T11:32:46.195+0000] {local_task_job_runner.py:228} INFO - Task exited with return code 0
[2025-03-07T11:32:46.214+0000] {taskinstance.py:2778} INFO - 1 downstream tasks scheduled from follow-on schedule check
